<?xml version="1.0" ?>
<!-- Generated using onshape-to-robot -->
<!-- Onshape https://cad.onshape.com/documents/971c71e558f4d758be7c1282/w/a52d355fced062b7019a3a28/e/242e269d7b3e3af20cba21dc -->
<robot name="cora">
  <!-- Link base_link -->
  <link name="base_link">
    <inertial>
      <origin xyz="0 0 0" rpy="0 0 0"/>
      <mass value="1e-09"/>
      <inertia ixx="1e-09" ixy="0" ixz="0" iyy="1e-09" iyz="0" izz="1e-09"/>
    </inertial>
  </link>
  <!-- Link baselink -->
  <link name="baselink">
    <inertial>
      <origin xyz="-8.1956e-10 -3.65639e-06 0.117444" rpy="0 0 0"/>
      <mass value="0.24516"/>
      <inertia ixx="0.000323987" ixy="-7.28045e-12" ixz="9.47353e-13" iyy="0.000311847" iyz="4.08315e-09" izz="0.000593318"/>
    </inertial>
    <!-- Part baselink_parts -->
    <visual>
      <origin xyz="-8.1956e-10 -3.65639e-06 0.117444" rpy="0 -0 0"/>
      <geometry>
        <mesh filename="package://cora_description/meshes/cora/merged/baselink_visual.stl"/>
      </geometry>
      <material name="baselink_parts_material">
        <color rgba="0.243744 0.341731 0.5466 1"/>
      </material>
    </visual>
    <collision>
      <origin xyz="-8.1956e-10 -3.65639e-06 0.117444" rpy="0 -0 0"/>
      <geometry>
        <mesh filename="package://cora_description/meshes/cora/merged/baselink_collision.stl"/>
      </geometry>
    </collision>
  </link>
  <!-- Link l1 -->
  <link name="l1">
    <inertial>
      <origin xyz="0.0191928 0.0110806 -0.0814544" rpy="0 0 0"/>
      <mass value="0.953925"/>
      <inertia ixx="0.0038825" ixy="-0.000254133" ixz="0.000201561" iyy="0.0041759" iyz="0.000116327" izz="0.00342708"/>
    </inertial>
    <!-- Part l1_parts -->
    <visual>
      <origin xyz="0.0191928 0.0110806 -0.0814544" rpy="3.14159 -7.80145e-16 0.523599"/>
      <geometry>
        <mesh filename="package://cora_description/meshes/cora/merged/l1_visual.stl"/>
      </geometry>
      <material name="l1_parts_material">
        <color rgba="0.333158 0.371302 0.428465 0.935322"/>
      </material>
    </visual>
    <collision>
      <origin xyz="0.0191928 0.0110806 -0.0814544" rpy="3.14159 -7.80145e-16 0.523599"/>
      <geometry>
        <mesh filename="package://cora_description/meshes/cora/merged/l1_collision.stl"/>
      </geometry>
    </collision>
  </link>
  <!-- Link l2 -->
  <link name="l2">
    <inertial>
      <origin xyz="0.194271 0.112163 -0.082967" rpy="0 0 0"/>
      <mass value="2.493"/>
      <inertia ixx="0.0302314" ixy="-0.0376637" ixz="-3.00765e-05" iyy="0.0736754" iyz="-1.73647e-05" izz="0.0936367"/>
    </inertial>
    <!-- Part l2_parts -->
    <visual>
      <origin xyz="0.194271 0.112163 -0.082967" rpy="-0.523599 1.5708 0"/>
      <geometry>
        <mesh filename="package://cora_description/meshes/cora/merged/l2_visual.stl"/>
      </geometry>
      <material name="l2_parts_material">
        <color rgba="0.352647 0.388789 0.438704 0.950503"/>
      </material>
    </visual>
    <collision>
      <origin xyz="0.194271 0.112163 -0.082967" rpy="-0.523599 1.5708 0"/>
      <geometry>
        <mesh filename="package://cora_description/meshes/cora/merged/l2_collision.stl"/>
      </geometry>
    </collision>
  </link>
  <!-- Link l3 -->
  <link name="l3">
    <inertial>
      <origin xyz="4.64901e-07 -0.171257 -0.0792607" rpy="0 0 0"/>
      <mass value="0.938652"/>
      <inertia ixx="0.0197676" ixy="-2.13048e-10" ixz="3.14699e-08" iyy="0.00235754" iyz="-0.00168846" izz="0.0192461"/>
    </inertial>
    <!-- Part l3_parts -->
    <visual>
      <origin xyz="4.64901e-07 -0.171257 -0.0792607" rpy="1.5708 -1.5708 0"/>
      <geometry>
        <mesh filename="package://cora_description/meshes/cora/merged/l3_visual.stl"/>
      </geometry>
      <material name="l3_parts_material">
        <color rgba="0.373422 0.40919 0.458317 0.972899"/>
      </material>
    </visual>
    <collision>
      <origin xyz="4.64901e-07 -0.171257 -0.0792607" rpy="1.5708 -1.5708 0"/>
      <geometry>
        <mesh filename="package://cora_description/meshes/cora/merged/l3_collision.stl"/>
      </geometry>
    </collision>
  </link>
  <!-- Link l4 -->
  <link name="l4">
    <inertial>
      <origin xyz="-4.28168e-07 0.0063774 -0.0558952" rpy="0 0 0"/>
      <mass value="0.380512"/>
      <inertia ixx="0.0011083" ixy="-1.31383e-08" ixz="-5.44594e-09" iyy="0.000909031" iyz="7.12784e-05" izz="0.000977838"/>
    </inertial>
    <!-- Part l4_parts -->
    <visual>
      <origin xyz="-4.28168e-07 0.0063774 -0.0558952" rpy="-1.5708 1.5708 0"/>
      <geometry>
        <mesh filename="package://cora_description/meshes/cora/merged/l4_visual.stl"/>
      </geometry>
      <material name="l4_parts_material">
        <color rgba="0.324789 0.344876 0.368236 0.933148"/>
      </material>
    </visual>
    <collision>
      <origin xyz="-4.28168e-07 0.0063774 -0.0558952" rpy="-1.5708 1.5708 0"/>
      <geometry>
        <mesh filename="package://cora_description/meshes/cora/merged/l4_collision.stl"/>
      </geometry>
    </collision>
  </link>
  <!-- Link l5 -->
  <link name="l5">
    <inertial>
      <origin xyz="-4.28168e-07 0.0063774 -0.0558952" rpy="0 0 0"/>
      <mass value="0.380512"/>
      <inertia ixx="0.0011083" ixy="-1.31383e-08" ixz="-5.44594e-09" iyy="0.000909031" iyz="7.12784e-05" izz="0.000977838"/>
    </inertial>
    <!-- Part l5_parts -->
    <visual>
      <origin xyz="-4.28168e-07 0.0063774 -0.0558952" rpy="-3.14159 -8.39713e-15 -1.5708"/>
      <geometry>
        <mesh filename="package://cora_description/meshes/cora/merged/l5_visual.stl"/>
      </geometry>
      <material name="l5_parts_material">
        <color rgba="0.324789 0.344876 0.368236 0.933148"/>
      </material>
    </visual>
    <collision>
      <origin xyz="-4.28168e-07 0.0063774 -0.0558952" rpy="-3.14159 -8.39713e-15 -1.5708"/>
      <geometry>
        <mesh filename="package://cora_description/meshes/cora/merged/l5_collision.stl"/>
      </geometry>
    </collision>
  </link>
  <!-- Link endeffector -->
  <link name="endeffector">
    <inertial>
      <origin xyz="0 0 0" rpy="0 0 0"/>
      <mass value="1e-09"/>
      <inertia ixx="1e-09" ixy="0" ixz="0" iyy="1e-09" iyz="0" izz="1e-09"/>
    </inertial>
    <!-- Part endeffector_parts -->
    <visual>
      <origin xyz="1.17217 5.74112e-15 -0.083" rpy="1.42696e-14 -1.5708 0"/>
      <geometry>
        <mesh filename="package://cora_description/meshes/cora/merged/endeffector_visual.stl"/>
      </geometry>
      <material name="endeffector_parts_material">
        <color rgba="0.4 0.4 0.4 1.0"/>
      </material>
    </visual>
    <collision>
      <origin xyz="1.17217 5.74112e-15 -0.083" rpy="1.42696e-14 -1.5708 0"/>
      <geometry>
        <mesh filename="package://cora_description/meshes/cora/merged/endeffector_collision.stl"/>
      </geometry>
    </collision>
  </link>
  <!-- Joint from l5 to endeffector -->
  <joint name="J6" type="revolute">
    <origin xyz="-1.79316e-15 0.0801667 -0.075" rpy="1.5708 -1.5708 0"/>
    <parent link="l5"/>
    <child link="endeffector"/>
    <axis xyz="0 0 1"/>
    <limit effort="10" velocity="2" lower="-3.14" upper="3.14"/>
    <joint_properties friction="0.1"/>
  </joint>
  <!-- Joint from l4 to l5 -->
  <joint name="J5" type="revolute">
    <origin xyz="4.46411e-16 0.0811667 -0.075" rpy="1.5708 -6.65049e-14 -4.10783e-15"/>
    <parent link="l4"/>
    <child link="l5"/>
    <axis xyz="0 0 1"/>
    <limit effort="10" velocity="2" lower="-3.14" upper="3.14"/>
    <joint_properties friction="0.1"/>
  </joint>
  <!-- Joint from l3 to l4 -->
  <joint name="J4" type="revolute">
    <origin xyz="-2.23477e-15 -0.335 -0.0138333" rpy="-3.14159 -5.25775e-15 -1.77358e-14"/>
    <parent link="l3"/>
    <child link="l4"/>
    <axis xyz="0 0 1"/>
    <limit effort="10" velocity="2" lower="-3.14" upper="3.14"/>
    <joint_properties friction="0.1"/>
  </joint>
  <!-- Joint from l2 to l3 -->
  <joint name="J3" type="revolute">
    <origin xyz="0.393176 0.227 0.002" rpy="-3.14159 -1.73694e-15 -1.0472"/>
    <parent link="l2"/>
    <child link="l3"/>
    <axis xyz="0 0 1"/>
    <limit effort="10" velocity="2" lower="-3.14" upper="3.14"/>
    <joint_properties friction="0.1"/>
  </joint>
  <!-- Joint from l1 to l2 -->
  <joint name="J2" type="revolute">
    <origin xyz="0.0900666 0.052 -0.088" rpy="-1.5708 1.0472 2.0944"/>
    <parent link="l1"/>
    <child link="l2"/>
    <axis xyz="0 0 1"/>
    <limit effort="10" velocity="2" lower="-3.14" upper="3.14"/>
    <joint_properties friction="0.1"/>
  </joint>
  <!-- Joint from baselink to l1 -->
  <joint name="J1" type="revolute">
    <origin xyz="1.08655e-17 -5.35667e-26 0.139" rpy="-3.14159 -1.07316e-15 0.523599"/>
    <parent link="baselink"/>
    <child link="l1"/>
    <axis xyz="0 0 1"/>
    <limit effort="10" velocity="2" lower="-3.14" upper="3.14"/>
    <joint_properties friction="0.1"/>
  </joint>
  <!-- Joint from base_link to baselink -->
  <joint name="base_link_to_baselink" type="fixed">
    <origin xyz="0 0 0" rpy="0 -0 0"/>
    <parent link="base_link"/>
    <child link="baselink"/>
    <axis xyz="0 0 1"/>
    <limit effort="10" velocity="10"/>
  </joint>
</robot>
